<?xml version="1.0" ?>
<!-- =================================================================================== -->
<!-- |    This document was autogenerated by xacro from /home/bamertsa/catkin_ws/src/HelMoRo-software/helmoro_description/urdf/helmoro.urdf | -->
<!-- |    EDITING THIS FILE BY HAND IS NOT RECOMMENDED                                 | -->
<!-- =================================================================================== -->
<robot name="Helmoro">
  <material name="HELMORO_BLUE">
    <color rgba="0.3 0.78 1.0 1.0"/>
    <!-- rviz green color -->
  </material>
  <material name="HELMORO_BLACK">
    <color rgba="0.0 0.0 0.0 1.0"/>
    <!-- rviz green color -->
  </material>
  <!--joints for camera_link-->
  <joint name="camera_link_joint" type="fixed">
    <origin rpy="0 0 0" xyz="0 0 0"/>
    <parent link="camera_mesh"/>
    <child link="camera_link"/>
  </joint>
  <link name="camera_link"/>
  <!--joints for rgb_camera-->
  <joint name="camera_rgb_frame_joint" type="fixed">
    <origin rpy="0 0 0" xyz="0 0.045 0"/>
    <parent link="camera_link"/>
    <child link="camera_rgb_frame"/>
  </joint>
  <link name="camera_rgb_frame"/>
  <joint name="camera_rgb_optical_frame_joint" type="fixed">
    <origin rpy="-1.5707963267948966 0 -1.5707963267948966" xyz="0 0 0"/>
    <parent link="camera_rgb_frame"/>
    <child link="camera_rgb_optical_frame"/>
  </joint>
  <link name="camera_rgb_optical_frame"/>
  <!--joints for depth_camera-->
  <joint name="camera_depth_frame_joint" type="fixed">
    <origin rpy="0 0 0" xyz="0 0.02 0"/>
    <parent link="camera_link"/>
    <child link="camera_depth_frame"/>
  </joint>
  <link name="camera_depth_frame"/>
  <joint name="camera_rgb_depth_frame_joint" type="fixed">
    <origin rpy="-1.5707963267948966 0 -1.5707963267948966" xyz="0 0 0"/>
    <parent link="camera_depth_frame"/>
    <child link="camera_depth_optical_frame"/>
  </joint>
  <link name="camera_depth_optical_frame"/>
  <!-- joints for the center of the fork-->
  <joint name="fork_joint" type="fixed">
    <origin rpy="0 0 0" xyz="0.13 0 0"/>
    <parent link="base_link"/>
    <child link="fork_frame"/>
  </joint>
  <link name="fork_frame"/>
  <gazebo>
    <plugin filename="libhelmoro_gazebo_plugin.so" name="helmoro_gazebo_plugin"/>
  </gazebo>
  <gazebo reference="camera_rgb_frame">
    <sensor name="camera" type="depth">
      <update_rate>30</update_rate>
      <camera>
        <horizontal_fov>1.0471975511965976</horizontal_fov>
        <image>
          <width>640</width>
          <height>480</height>
          <format>R8G8B8</format>
        </image>
        <clip>
          <near>0.45</near>
          <far>8</far>
        </clip>
      </camera>
      <plugin filename="libgazebo_ros_openni_kinect.so" name="camera_link_controller">
        <baseline>0.2</baseline>
        <alwaysOn>true</alwaysOn>
        <updateRate>0.0</updateRate>
        <!--1.0-->
        <cameraName>astra_pro_ir</cameraName>
        <imageTopicName>/camera/rgb/image_raw</imageTopicName>
        <cameraInfoTopicName>/camera/rgb/camera_info</cameraInfoTopicName>
        <depthImageTopicName>/camera/depth/image_raw</depthImageTopicName>
        <depthImageInfoTopicName>/camera/depth/camera_info</depthImageInfoTopicName>
        <pointCloudTopicName>/camera/depth/points</pointCloudTopicName>
        <frameName>camera_rgb_optical_frame</frameName>
        <pointCloudCutoff>0.45</pointCloudCutoff>
        <pointCloudCutoffMax>8</pointCloudCutoffMax>
        <distortionK1>0.00000001</distortionK1>
        <distortionK2>0.00000001</distortionK2>
        <distortionK3>0.00000001</distortionK3>
        <distortionT1>0.00000001</distortionT1>
        <distortionT2>0.00000001</distortionT2>
        <CxPrime>0</CxPrime>
        <Cx>0</Cx>
        <Cy>0</Cy>
        <focalLength>0</focalLength>
        <hackBaseline>0</hackBaseline>
      </plugin>
    </sensor>
  </gazebo>
  <gazebo reference="laser">
    <sensor name="rplidar" type="ray">
      <pose>0 0 0 0 0 0</pose>
      <visualize>false</visualize>
      <update_rate>10</update_rate>
      <ray>
        <scan>
          <horizontal>
            <samples>720</samples>
            <resolution>1</resolution>
            <min_angle>0</min_angle>
            <!--0 degrees-->
            <max_angle>6.283185307179586</max_angle>
            <!--360 degrees-->
          </horizontal>
        </scan>
        <range>
          <min>0.15</min>
          <!--should be 0.15-->
          <max>12.0</max>
          <resolution>0.01</resolution>
        </range>
        <noise>
          <type>gaussian</type>
          <!-- Noise parameters based on published spec for Hokuyo laser
               achieving "+-30mm" accuracy at range < 10m.  A mean of 0.0m and
               stddev of 0.01m will put 99.7% of samples within 0.03m of the true
               reading. -->
          <mean>0.0</mean>
          <stddev>0.01</stddev>
        </noise>
      </ray>
      <plugin filename="libgazebo_ros_laser.so" name="gazebo_ros_head_hokuyo_controller">
        <topicName>/scan</topicName>
        <frameName>laser</frameName>
      </plugin>
    </sensor>
  </gazebo>
  <gazebo reference="imu_link">
    <gravity>true</gravity>
    <sensor name="imu_sensor" type="imu">
      <always_on>true</always_on>
      <update_rate>100</update_rate>
      <visualize>true</visualize>
      <topic>__default_topic__</topic>
      <plugin filename="libgazebo_ros_imu_sensor.so" name="imu_plugin">
        <topicName>imu/data</topicName>
        <bodyName>imu_link</bodyName>
        <updateRateHZ>10.0</updateRateHZ>
        <gaussianNoise>0.0</gaussianNoise>
        <xyzOffset>0 0 0</xyzOffset>
        <rpyOffset>0 0 0</rpyOffset>
        <frameName>imu_link</frameName>
      </plugin>
      <pose>0 0 0 0 0 0</pose>
    </sensor>
  </gazebo>
  <!-- Link 1 -->
  <link name="base_link">
    <visual>
      <origin rpy="0 0 0" xyz="0 0 0"/>
      <geometry>
        <mesh filename="package://helmoro_description/meshes/Cover.STL"/>
      </geometry>
      <material name="HELMORO_BLUE"/>
      <!-- rviz will use this color -->
    </visual>
    <collision>
      <origin rpy="0 0 0" xyz="0 0 0.034"/>
      <geometry>
        <box size="0.09 0.256 0.11"/>
      </geometry>
    </collision>
  </link>
  <!-- Dummy inertia link, because KDL cannot have inertia on the base link -->
  <link name="base_link_inertia">
    <inertial>
      <origin rpy="0 0 0" xyz="0 0 0"/>
      <mass value="1.0"/>
      <inertia ixx="0.006667" ixy="0" ixz="0" iyy="0.006667" iyz="0" izz="0.006667"/>
    </inertial>
  </link>
  <!-- Fixed joint to add dummy inertia link -->
  <joint name="base_link_to_base_link_inertia" type="fixed">
    <parent link="base_link"/>
    <child link="base_link_inertia"/>
    <origin rpy="0 0 0" xyz="0 0 0"/>
  </joint>
  <!-- Link 2 -->
  <link name="RIGHT_FRONT_WHEEL">
    <visual>
      <origin rpy="0 0 0" xyz="0 0 -0.005"/>
      <geometry>
        <cylinder length="0.01" radius="0.045"/>
      </geometry>
      <material name="HELMORO_BLACK"/>
      <!-- rviz will use this color -->
    </visual>
    <collision>
      <origin rpy="0 0 0" xyz="0 0 -0.005"/>
      <geometry>
        <cylinder length="0.01" radius="0.045"/>
      </geometry>
      <surface>
        <friction>
          <fdir1>1 0 0</fdir1>
          <kp>1000000</kp>
          <!-- kp and kd for rubber -->
          <kd>100</kd>
          <mu>1</mu>
          <mu2>1</mu2>
          <slip1>0.5</slip1>
          <slip2>0</slip2>
        </friction>
      </surface>
    </collision>
    <inertial>
      <origin rpy="0 0 0" xyz="0 0 0.005"/>
      <mass value="1"/>
      <inertia ixx="0.0005145833333333333" ixy="0" ixz="0" iyy="0.0005145833333333333" iyz="0" izz="0.0010125"/>
    </inertial>
  </link>
  <joint name="base_link_to_RIGHT_FRONT_WHEEL" type="continuous">
    <parent link="base_link"/>
    <child link="RIGHT_FRONT_WHEEL"/>
    <origin rpy="-1.5707963267948966 0 0" xyz="0.0575 -0.0925 -0.035"/>
    <axis xyz="0 0 1"/>
  </joint>
  <!-- Link 3 -->
  <link name="LEFT_FRONT_WHEEL">
    <visual>
      <origin rpy="0 0 0" xyz="0 0 0.005"/>
      <geometry>
        <cylinder length="0.01" radius="0.045"/>
      </geometry>
      <material name="HELMORO_BLACK"/>
      <!-- rviz will use this color -->
    </visual>
    <collision>
      <origin rpy="0 0 0" xyz="0 0 0.005"/>
      <geometry>
        <cylinder length="0.01" radius="0.045"/>
      </geometry>
      <material name="HELMORO_BLACK"/>
      <!-- rviz will use this color -->
      <surface>
        <friction>
          <fdir1>1 0 0</fdir1>
          <kp>1000000</kp>
          <!-- kp and kd for rubber -->
          <kd>100</kd>
          <mu>1</mu>
          <mu2>1</mu2>
          <slip1>0.5</slip1>
          <slip2>0</slip2>
        </friction>
      </surface>
    </collision>
    <inertial>
      <origin rpy="0 0 0" xyz="0 0 -0.005"/>
      <mass value="1"/>
      <inertia ixx="0.0005145833333333333" ixy="0" ixz="0" iyy="0.0005145833333333333" iyz="0" izz="0.0010125"/>
    </inertial>
  </link>
  <joint name="base_link_to_LEFT_FRONT_WHEEL" type="continuous">
    <parent link="base_link"/>
    <child link="LEFT_FRONT_WHEEL"/>
    <origin rpy="-1.5707963267948966 0 0" xyz="0.0575 0.0925 -0.035"/>
    <axis xyz="0 0 1"/>
  </joint>
  <!-- Link 4 -->
  <link name="RIGHT_BACK_WHEEL">
    <visual>
      <origin rpy="0 0 0" xyz="0 0 -0.005"/>
      <geometry>
        <cylinder length="0.01" radius="0.045"/>
      </geometry>
      <material name="HELMORO_BLACK"/>
      <!-- rviz will use this color -->
    </visual>
    <collision>
      <origin rpy="0 0 0" xyz="0 0 -0.005"/>
      <geometry>
        <cylinder length="0.01" radius="0.045"/>
      </geometry>
      <surface>
        <friction>
          <fdir1>1 0 0</fdir1>
          <kp>1000000</kp>
          <!-- kp and kd for rubber -->
          <kd>100</kd>
          <mu>1</mu>
          <mu2>1</mu2>
          <slip1>0.5</slip1>
          <slip2>0</slip2>
        </friction>
      </surface>
    </collision>
    <inertial>
      <origin rpy="0 0 0" xyz="0 0 0.005"/>
      <mass value="1"/>
      <inertia ixx="0.0005145833333333333" ixy="0" ixz="0" iyy="0.0005145833333333333" iyz="0" izz="0.0010125"/>
    </inertial>
  </link>
  <joint name="base_link_to_RIGHT_BACK_WHEEL" type="continuous">
    <parent link="base_link"/>
    <child link="RIGHT_BACK_WHEEL"/>
    <origin rpy="-1.5707963267948966 0 0" xyz="-0.0575 -0.0925 -0.035"/>
    <axis xyz="0 0 1"/>
  </joint>
  <!-- Link 5 -->
  <link name="LEFT_BACK_WHEEL">
    <visual>
      <origin rpy="0 0 0" xyz="0 0 0.005"/>
      <geometry>
        <cylinder length="0.01" radius="0.045"/>
      </geometry>
      <material name="HELMORO_BLACK"/>
      <!-- rviz will use this color -->
    </visual>
    <collision>
      <origin rpy="0 0 0" xyz="0 0 0.005"/>
      <geometry>
        <cylinder length="0.01" radius="0.045"/>
      </geometry>
      <surface>
        <friction>
          <fdir1>1 0 0</fdir1>
          <kp>1000000</kp>
          <!-- kp and kd for rubber -->
          <kd>100</kd>
          <mu>10</mu>
          <mu2>10</mu2>
          <slip1>0.5</slip1>
          <slip2>0</slip2>
        </friction>
      </surface>
    </collision>
    <inertial>
      <origin rpy="0 0 0" xyz="0 0 -0.005"/>
      <mass value="1"/>
      <inertia ixx="0.0005145833333333333" ixy="0" ixz="0" iyy="0.0005145833333333333" iyz="0" izz="0.0010125"/>
    </inertial>
  </link>
  <joint name="base_link_to_LEFT_BACK_WHEEL" type="continuous">
    <parent link="base_link"/>
    <child link="LEFT_BACK_WHEEL"/>
    <origin rpy="-1.5707963267948966 0 0" xyz="-0.0575 0.0925 -0.035"/>
    <axis xyz="0 0 1"/>
  </joint>
  <link name="camera_mesh">
    <visual>
      <origin rpy="0 0 0" xyz="0 0 0"/>
      <geometry>
        <mesh filename="package://helmoro_description/meshes/Orbbec Astra Camera No Mount 2.STL"/>
      </geometry>
      <material name="HELMORO_BLACK"/>
      <!-- rviz will use this color -->
    </visual>
    <inertial>
      <origin rpy="0 0 0" xyz="0 0 0"/>
      <mass value="0.1"/>
      <inertia ixx="0.1" ixy="0" ixz="0" iyy="0.1" iyz="0" izz="0.1"/>
    </inertial>
  </link>
  <joint name="base_link_to_camera_mesh" type="fixed">
    <parent link="base_link"/>
    <child link="camera_mesh"/>
    <origin rpy="0 0 0" xyz="0.114 0 0.038"/>
  </joint>
  <link name="laser">
    <visual>
      <origin rpy="0 0 0" xyz="0 0 0"/>
      <geometry>
        <mesh filename="package://helmoro_description/meshes/lidar_ROS_V3.STL"/>
      </geometry>
      <material name="HELMORO_BLACK"/>
      <!-- rviz will use this color -->
    </visual>
    <inertial>
      <origin rpy="0 0 0" xyz="0 0 0"/>
      <mass value="0.1"/>
      <inertia ixx="0.1" ixy="0" ixz="0" iyy="0.1" iyz="0" izz="0.1"/>
    </inertial>
  </link>
  <joint name="base_link_to_laser" type="fixed">
    <parent link="base_link"/>
    <child link="laser"/>
    <origin rpy="0 0 -1.5707963267948966" xyz="0.01 0 0.0658"/>
  </joint>
  <link name="imu_link">
    <visual>
      <origin rpy="0 0 0" xyz="0 0 0"/>
      <geometry>
        <box size="0.02032 0.02667 0.00415"/>
      </geometry>
    </visual>
    <inertial>
      <origin rpy="0 0 0" xyz="0 0 0"/>
      <mass value="1.0"/>
      <inertia ixx="0.1" ixy="0" ixz="0" iyy="0.1" iyz="0" izz="0.1"/>
    </inertial>
  </link>
  <joint name="base_link_to_imu_link" type="fixed">
    <parent link="base_link"/>
    <child link="imu_link"/>
    <origin rpy="0 0 0" xyz="-0 0 0.001"/>
  </joint>
  <gazebo reference="RIGHT_FRONT_WHEEL">
    <collision>
      <surface>
        <friction>
          <ode>
            <mu>5</mu>
            <mu2>5</mu2>
          </ode>
        </friction>
        <contact>
          <ode>
            <kp>1000000</kp>
            <!-- kp and kd for rubber -->
            <kd>100</kd>
          </ode>
        </contact>
      </surface>
    </collision>
  </gazebo>
  <gazebo reference="LEFT_FRONT_WHEEL">
    <collision>
      <surface>
        <friction>
          <ode>
            <mu>5</mu>
            <mu2>5</mu2>
          </ode>
        </friction>
        <contact>
          <ode>
            <kp>1000000</kp>
            <!-- kp and kd for rubber -->
            <kd>100</kd>
          </ode>
        </contact>
      </surface>
    </collision>
  </gazebo>
  <gazebo reference="RIGHT_BACK_WHEEL">
    <collision>
      <surface>
        <friction>
          <ode>
            <mu>5</mu>
            <mu2>5</mu2>
          </ode>
        </friction>
        <contact>
          <ode>
            <kp>1000000</kp>
            <!-- kp and kd for rubber -->
            <kd>100</kd>
          </ode>
        </contact>
      </surface>
    </collision>
  </gazebo>
  <gazebo reference="LEFT_BACK_WHEEL">
    <collision>
      <surface>
        <friction>
          <ode>
            <mu>5</mu>
            <mu2>5</mu2>
          </ode>
        </friction>
        <contact>
          <ode>
            <kp>1000000</kp>
            <!-- kp and kd for rubber -->
            <kd>100</kd>
          </ode>
        </contact>
      </surface>
    </collision>
  </gazebo>
</robot>


